Workbook

Sheet Date range
A1: Last X Months | B1: 6 | C1: 45808

Sheet Past transactions
A1: Transaction Id | B1: Date | C1: Amount | D1: Name | E1: Category | F1: Memo | G1: Column 3
B2: 45833 | C2: 27.5 | E2: Software | F2: GC<>HUBOO TECH HU-MDQR59Q XXXXXXXX23512 Intl Electronic Debit | G2: =C2*-1 -> -27.5
B3: 45833 | C3: -179.62 | E3: Shopify | F3: SHOPIFY TRANSFER SHOPIFY Electronic Deposit | G3: =C3*-1 -> 179.62
B4: 45833 | C4: -55.34 | E4: Shopify | F4: Shopify TRANSFER ST-O8T3U5A0U9X0 Electronic Deposit | G4: =C4*-1 -> 55.34
B5: 45833 | C5: -592.64 | E5: Shopify | F5: Shopify TRANSFER ST-X1D3L3K8Q0O3 Electronic Deposit | G5: =C5*-1 -> 592.64
B6: 45833 | C6: -110.68 | E6: Shopify | F6: SHOPPAYINST AFRM PAYMENTS 4ZNMOY7IEOH6GG3 Electronic Deposit | G6: =C6*-1 -> 110.68
B7: 45832 | C7: 0.01 | E7: Tax Expenditures | F7: VA DEPT TAXATION TAX PAYMEN *****4666 Electronic Debit | G7: =C7*-1 -> -0.01
B8: 45832 | C8: -340 | E8: Shopify | F8: SHOPIFY TRANSFER SHOPIFY Electronic Deposit | G8: =C8*-1 -> 340
B9: 45832 | C9: -3521.59 | E9: Shopify | F9: SHOPIFY TRANSFER ST-C2N3H8H4R3M2 Electronic Deposit | G9: =C9*-1 -> 3521.59
B10: 45831 | C10: 250.51 | E10: Software | F10: INTUIT * QBooks Onl 8667280 Electronic Debit | G10: =C10*-1 -> -250.51
B11: 45831 | C11: -55.05 | E11: Shopify | F11: SHOPIFY TRANSFER SHOPIFY Electronic Deposit | G11: =C11*-1 -> 55.05
B12: 45831 | C12: -2271.5 | E12: Shopify | F12: Shopify TRANSFER ST-D9V1Y5G8R1X2 Electronic Deposit | G12: =C12*-1 -> 2271.5
B13: 45831 | C13: -217.53 | E13: Shopify | F13: SHOPIFY TRANSFER SHOPIFY Electronic Deposit | G13: =C13*-1 -> 217.53
... B20: 45828 | C20: 369.3 | E20: Tax Expenditures | F20: GEORGIA ITS TAX GA TX PYMT XXXXXX5216 Electronic Debit | G20: =C20*-1 -> -369.3
B21: 45828 | C21: 905.09 | D21: The Hartford | E21: Overhead Expenditures | F21: THE HARTFORD INSPMTCL 17122542 Electronic Debit | G21: =C21*-1 -> -905.09
B22: 45828 | C22: 1086.26 | E22: Tax Expenditures | F22: WEBFILE TAX PYMT DD 902/79387750 Electronic Debit | G22: =C22*-1 -> -1086.26
B23: 45828 | C23: -623.59 | D23: Shopify | E23: Shopify | F23: Shopify TRANSFER ST-W1M2I0T4O1U1 Electronic Deposit | G23: =C23*-1 -> 623.59
B24: 45828 | C24: -120.91 | D24: Shopify | E24: Shopify | F24: SHOPPAYINST AFRM PAYMENTS UYK2YKTRBEN7TU5 Electronic Deposit | G24: =C24*-1 -> 120.91
B25: 45828 | C25: -134.41 | D25: Shopify | E25: Shopify | F25: SHOPIFY TRANSFER SHOPIFY Electronic Deposit | G25: =C25*-1 -> 134.41
B26: 45826 | C26: 27.89 | D26: Huboo | E26: Software | F26: GC<>HUBOO TECH HU-MDQR59Q XXXXXXXX23512 Intl Electronic Debit | G26: =C26*-1 -> -27.89
B27: 45826 | C27: 123.86 | D27: Shopify | E27: Shopify | F27: SHOPIFY XXXXXXXXXX VOCHILL Electronic Debit | G27: =C27*-1 -> -123.86
B28: 45826 | C28: 270.59 | D28: Virginia Department of Taxation | E28: Tax Expenditures | F28: VA DEPT TAXATION TAX PAYMEN *****4666 Electronic Debit | G28: =C28*-1 -> -270.59
B29: 45826 | C29: -205.81 | D29: Shopify | E29: Shopify | F29: SHOPIFY TRANSFER SHOPIFY Electronic Deposit | G29: =C29*-1 -> 205.81
B30: 45826 | C30: -55.59 | D30: Shopify | E30: Shopify | F30: SHOPIFY TRANSFER ST-O7P1K1P2B1R8 Electronic Deposit | G30: =C30*-1 -> 55.59
B31: 45826 | C31: -408.66 | D31: Shopify | E31: Shopify | F31: SHOPIFY TRANSFER ST-Y7U7O5V2D6V7 Electronic Deposit | G31: =C31*-1 -> 408.66
B32: 45825 | C32: 40 | E32: Overhead Expenditures | F32: Treasury Mgmt Svcs | G32: =C32*-1 -> -40
B33: 45825 | C33: 94.72 | E33: Overhead Expenditures | F33: BILL.COM LLC BILLING 02B4JTVUDQMT00M Electronic Debit | G33: =C33*-1 -> -94.72
B34: 45825 | C34: -5196.75 | D34: Shopify | E34: Shopify | F34: Shopify TRANSFER ST-U2S0R0C9M1C1 Electronic Deposit | G34: =C34*-1 -> 5196.75
B35: 45825 | C35: -76.61 | D35: Shopify | E35: Shopify | F35: SHOPPAYINST AFRM PAYMENTS E7I6ZPF4BMK4LT2 Electronic Deposit | G35: =C35*-1 -> 76.61
B36: 45825 | C36: -255.93 | D36: Shopify | E36: Shopify | F36: SHOPIFY TRANSFER SHOPIFY Electronic Deposit | G36: =C36*-1 -> 255.93
B37: 45825 | C37: -44.26 | D37: Shopify | E37: Shopify | F37: SHOPPAYINST AFRM PAYMENTS 6KQEL2L4S9SW6WR Electronic Deposit | G37: =C37*-1 -> 44.26
B38: 45825 | C38: -170.51 | D38: Shopify | E38: Shopify | F38: SHOPPAYINST AFRM PAYMENTS 6X8YZ3TSTVZHIZG Electronic Deposit | G38: =C38*-1 -> 170.51
B39: 45824 | C39: 1.45 | E39: Overhead Expenditures | F39: GLOBAL - E PPD Electronic Debit | G39: =C39*-1 -> -1.45
B40: 45824 | C40: 36.02 | D40: Huboo | E40: Software | F40: GC<>HUBOO TECH HU-MDQR59Q XXXXXXXX23512 Intl Electronic Debit | G40: =C40*-1 -> -36.02
B41: 45824 | C41: -120.41 | D41: Shopify | E41: Shopify | F41: SHOPIFY TRANSFER SHOPIFY Electronic Deposit | G41: =C41*-1 -> 120.41
B42: 45824 | C42: -1120.64 | D42: Shopify | E42: Shopify | F42: Shopify TRANSFER ST-Y1A5D8Q1I8Z5 Electronic Deposit | G42: =C42*-1 -> 1120.64
B43: 45824 | C43: -235.36 | D43: Shopify | E43: Shopify | F43: SHOPIFY TRANSFER SHOPIFY Electronic Deposit | G43: =C43*-1 -> 235.36
B44: 45824 | C44: -79.9 | D44: Shopify | E44: Shopify | F44: SHOPIFY TRANSFER SHOPIFY Electronic Deposit | G44: =C44*-1 -> 79.9
B45: 45823 | C45: 11371.29 | E45: Credit Card | F45: Payment Thank You - Web | G45: =C45*-1 -> -11371.29
B46: 45821 | C46: -73.66 | D46: Shopify | E46: Shopify | F46: SHOPPAYINST AFRM PAYMENTS B0RL6T2D275UM8F Electronic Deposit | G46: =C46*-1 -> 73.66
...

Sheet Recurring Transactions
A1: First payment date | B1: Counterparty | C1: Description | D1: Amount | E1: Category | F1: Frequency | G1: =IFERROR(ROWSDUMMYFUNCTION(AUTOFILL("Repayment 1",IFS($F2="bi-weekly",$A2+CEILING(('13-week CF Forecast'!$B$1-$A2)/14,1)*14+14*(COLUMN()-7),$F2="weekly",$A2+CEILING(('13-week CF Forecast'!$B$1-$A2)/7,1)*7+7*(COLUMN()-7),$F2="monthly",DATE(YEAR($A2),MONTH($A2)+CEILING(DATEDIF($A2,'13-week CF Forecast'!$B$1,"m")+1,1)+COLUMN()-7,DAY($A2)),$F2="quarterly",DATE(YEAR($A2),MONTH($A2)+3*CEILING((DATEDIF($A2,'13-week CF Forecast'!$B$1,"m")+1)/3,1)+(COLUMN()-7)*3,DAY($A2)),$F2="yearly",DATE(YEAR($A2)+CEILING((DATEDIF($A2,'13-week CF Forecast'!$B$1,"y")+1),1)+COLUMN()-7,MONTH($A2),DAY($A2)),TRUE,""))),"Repayment 1") -> Repayment 1 | H1: =IFERROR(ROWSDUMMYFUNCTION(AUTOFILL(CONCATENATE("Repayment ",SLICE(G1," ",2)+1),IFS($F2="bi-weekly",$A2+CEILING(('13-week CF Forecast'!$B$1-$A2)/14,1)*14+14*(COLUMN()-7),$F2="weekly",$A2+CEILING(('13-week CF Forecast'!$B$1-$A2)/7,1)*7+7*(COLUMN()-7),$F2="monthly",DATE(YEAR($A2),MONTH($A2)+CEILING(DATEDIF($A2,'13-week CF Forecast'!$B$1,"m")+1,1)+COLUMN()-7,DAY($A2)),$F2="quarterly",DATE(YEAR($A2),MONTH($A2)+3*CEILING((DATEDIF($A2,'13-week CF Forecast'!$B$1,"m")+1)/3,1)+(COLUMN()-7)*3,DAY($A2)),$F2="yearly",DATE(YEAR($A2)+CEILING((DATEDIF($A2,'13-week CF Forecast'!$B$1,"y")+1),1)+COLUMN()-7,MONTH($A2),DAY($A2)),TRUE,""),1)),"Repayment 2") -> Repayment 2 | I1: =IFERROR(ROWSDUMMYFUNCTION(AUTOFILL(CONCATENATE("Repayment ",SLICE(H1," ",2)+1),IFS($F2="bi-weekly",$A2+CEILING(('13-week CF Forecast'!$B$1-$A2)/14,1)*14+14*(COLUMN()-7),$F2="weekly",$A2+CEILING(('13-week CF Forecast'!$B$1-$A2)/7,1)*7+7*(COLUMN()-7),$F2="monthly",DATE(YEAR($A2),MONTH($A2)+CEILING(DATEDIF($A2,'13-week CF Forecast'!$B$1,"m")+1,1)+COLUMN()-7,DAY($A2)),$F2="quarterly",DATE(YEAR($A2),MONTH($A2)+3*CEILING((DATEDIF($A2,'13-week CF Forecast'!$B$1,"m")+1)/3,1)+(COLUMN()-7)*3,DAY($A2)),$F2="yearly",DATE(YEAR($A2)+CEILING((DATEDIF($A2,'13-week CF Forecast'!$B$1,"y")+1),1)+COLUMN()-7,MONTH($A2),DAY($A2)),TRUE,""),1)),"Repayment 3") -> Repayment 3 | J1: =IFERROR(ROWSDUMMYFUNCTION(AUTOFILL(CONCATENATE("Repayment ",SLICE(I1," ",2)+1),IFS($F2="bi-weekly",$A2+CEILING(('13-week CF Forecast'!$B$1-$A2)/14,1)*14+14*(COLUMN()-7),$F2="weekly",$A2+CEILING(('13-week CF Forecast'!$B$1-$A2)/7,1)*7+7*(COLUMN()-7),$F2="monthly",DATE(YEAR($A2),MONTH($A2)+CEILING(DATEDIF($A2,'13-week CF Forecast'!$B$1,"m")+1,1)+COLUMN()-7,DAY($A2)),$F2="quarterly",DATE(YEAR($A2),MONTH($A2)+3*CEILING((DATEDIF($A2,'13-week CF Forecast'!$B$1,"m")+1)/3,1)+(COLUMN()-7)*3,DAY($A2)),$F2="yearly",DATE(YEAR($A2)+CEILING((DATEDIF($A2,'13-week CF Forecast'!$B$1,"y")+1),1)+COLUMN()-7,MONTH($A2),DAY($A2)),TRUE,""),1)),"Repayment 4") -> Repayment 4 | K1: =IFERROR(ROWSDUMMYFUNCTION(AUTOFILL(CONCATENATE("Repayment ",SLICE(J1," ",2)+1),IFS($F2="bi-weekly",$A2+CEILING(('13-week CF Forecast'!$B$1-$A2)/14,1)*14+14*(COLUMN()-7),$F2="weekly",$A2+CEILING(('13-week CF Forecast'!$B$1-$A2)/7,1)*7+7*(COLUMN()-7),$F2="monthly",DATE(YEAR($A2),MONTH($A2)+CEILING(DATEDIF($A2,'13-week CF Forecast'!$B$1,"m")+1,1)+COLUMN()-7,DAY($A2)),$F2="quarterly",DATE(YEAR($A2),MONTH($A2)+3*CEILING((DATEDIF($A2,'13-week CF Forecast'!$B$1,"m")+1)/3,1)+(COLUMN()-7)*3,DAY($A2)),$F2="yearly",DATE(YEAR($A2)+CEILING((DATEDIF($A2,'13-week CF Forecast'!$B$1,"y")+1),1)+COLUMN()-7,MONTH($A2),DAY($A2)),TRUE,""),1)),"Repayment 5") -> Repayment 5 | L1: =IFERROR(ROWSDUMMYFUNCTION(AUTOFILL(CONCATENATE("Repayment ",SLICE(K1," ",2)+1),IFS($F2="bi-weekly",$A2+CEILING(('13-week CF Forecast'!$B$1-$A2)/14,1)*14+14*(COLUMN()-7),$F2="weekly",$A2+CEILING(('13-week CF Forecast'!$B$1-$A2)/7,1)*7+7*(COLUMN()-7),$F2="monthly",DATE(YEAR($A2),MONTH($A2)+CEILING(DATEDIF($A2,'13-week CF Forecast'!$B$1,"m")+1,1)+COLUMN()-7,DAY($A2)),$F2="quarterly",DATE(YEAR($A2),MONTH($A2)+3*CEILING((DATEDIF($A2,'13-week CF Forecast'!$B$1,"m")+1)/3,1)+(COLUMN()-7)*3,DAY($A2)),$F2="yearly",DATE(YEAR($A2)+CEILING((DATEDIF($A2,'13-week CF Forecast'!$B$1,"y")+1),1)+COLUMN()-7,MONTH($A2),DAY($A2)),TRUE,""),1)),"Repayment 6") -> Repayment 6 | M1: =IFERROR(ROWSDUMMYFUNCTION(AUTOFILL(CONCATENATE("Repayment ",SLICE(L1," ",2)+1),IFS($F2="bi-weekly",$A2+CEILING(('13-week CF Forecast'!$B$1-$A2)/14,1)*14+14*(COLUMN()-7),$F2="weekly",$A2+CEILING(('13-week CF Forecast'!$B$1-$A2)/7,1)*7+7*(COLUMN()-7),$F2="monthly",DATE(YEAR($A2),MONTH($A2)+CEILING(DATEDIF($A2,'13-week CF Forecast'!$B$1,"m")+1,1)+COLUMN()-7,DAY($A2)),$F2="quarterly",DATE(YEAR($A2),MONTH($A2)+3*CEILING((DATEDIF($A2,'13-week CF Forecast'!$B$1,"m")+1)/3,1)+(COLUMN()-7)*3,DAY($A2)),$F2="yearly",DATE(YEAR($A2)+CEILING((DATEDIF($A2,'13-week CF Forecast'!$B$1,"y")+1),1)+COLUMN()-7,MONTH($A2),DAY($A2)),TRUE,""),1)),"Repayment 7") -> Repayment 7 | N1: =IFERROR(ROWSDUMMYFUNCTION(AUTOFILL(CONCATENATE("Repayment ",SLICE(M1," ",2)+1),IFS($F2="bi-weekly",$A2+CEILING(('13-week CF Forecast'!$B$1-$A2)/14,1)*14+14*(COLUMN()-7),$F2="weekly",$A2+CEILING(('13-week CF Forecast'!$B$1-$A2)/7,1)*7+7*(COLUMN()-7),$F2="monthly",DATE(YEAR($A2),MONTH($A2)+CEILING(DATEDIF($A2,'13-week CF Forecast'!$B$1,"m")+1,1)+COLUMN()-7,DAY($A2)),$F2="quarterly",DATE(YEAR($A2),MONTH($A2)+3*CEILING((DATEDIF($A2,'13-week CF Forecast'!$B$1,"m")+1)/3,1)+(COLUMN()-7)*3,DAY($A2)),$F2="yearly",DATE(YEAR($A2)+CEILING((DATEDIF($A2,'13-week CF Forecast'!$B$1,"y")+1),1)+COLUMN()-7,MONTH($A2),DAY($A2)),TRUE,""),1)),"Repayment 8") -> Repayment 8 | O1: =IFERROR(ROWSDUMMYFUNCTION(AUTOFILL(CONCATENATE("Repayment ",SLICE(N1," ",2)+1),IFS($F2="bi-weekly",$A2+CEILING(('13-week CF Forecast'!$B$1-$A2)/14,1)*14+14*(COLUMN()-7),$F2="weekly",$A2+CEILING(('13-week CF Forecast'!$B$1-$A2)/7,1)*7+7*(COLUMN()-7),$F2="monthly",DATE(YEAR($A2),MONTH($A2)+CEILING(DATEDIF($A2,'13-week CF Forecast'!$B$1,"m")+1,1)+COLUMN()-7,DAY($A2)),$F2="quarterly",DATE(YEAR($A2),MONTH($A2)+3*CEILING((DATEDIF($A2,'13-week CF Forecast'!$B$1,"m")+1)/3,1)+(COLUMN()-7)*3,DAY($A2)),$F2="yearly",DATE(YEAR($A2)+CEILING((DATEDIF($A2,'13-week CF Forecast'!$B$1,"y")+1),1)+COLUMN()-7,MONTH($A2),DAY($A2)),TRUE,""),1)),"Repayment 9") -> Repayment 9 | P1: =IFERROR(ROWSDUMMYFUNCTION(AUTOFILL(CONCATENATE("Repayment ",SLICE(O1," ",2)+1),IFS($F2="bi-weekly",$A2+CEILING(('13-week CF Forecast'!$B$1-$A2)/14,1)*14+14*(COLUMN()-7),$F2="weekly",$A2+CEILING(('13-week CF Forecast'!$B$1-$A2)/7,1)*7+7*(COLUMN()-7),$F2="monthly",DATE(YEAR($A2),MONTH($A2)+CEILING(DATEDIF($A2,'13-week CF Forecast'!$B$1,"m")+1,1)+COLUMN()-7,DAY($A2)),$F2="quarterly",DATE(YEAR($A2),MONTH($A2)+3*CEILING((DATEDIF($A2,'13-week CF Forecast'!$B$1,"m")+1)/3,1)+(COLUMN()-7)*3,DAY($A2)),$F2="yearly",DATE(YEAR($A2)+CEILING((DATEDIF($A2,'13-week CF Forecast'!$B$1,"y")+1),1)+COLUMN()-7,MONTH($A2),DAY($A2)),TRUE,""),1)),"Repayment 10") -> Repayment 10 | Q1: =IFERROR(ROWSDUMMYFUNCTION(AUTOFILL(CONCATENATE("Repayment ",SLICE(P1," ",2)+1),IFS($F2="bi-weekly",$A2+CEILING(('13-week CF Forecast'!$B$1-$A2)/14,1)*14+14*(COLUMN()-7),$F2="weekly",$A2+CEILING(('13-week CF Forecast'!$B$1-$A2)/7,1)*7+7*(COLUMN()-7),$F2="monthly",DATE(YEAR($A2),MONTH($A2)+CEILING(DATEDIF($A2,'13-week CF Forecast'!$B$1,"m")+1,1)+COLUMN()-7,DAY($A2)),$F2="quarterly",DATE(YEAR($A2),MONTH($A2)+3*CEILING((DATEDIF($A2,'13-week CF Forecast'!$B$1,"m")+1)/3,1)+(COLUMN()-7)*3,DAY($A2)),$F2="yearly",DATE(YEAR($A2)+CEILING((DATEDIF($A2,'13-week CF Forecast'!$B$1,"y")+1),1)+COLUMN()-7,MONTH($A2),DAY($A2)),TRUE,""),1)),"Repayment 11") -> Repayment 11 | R1: =IFERROR(ROWSDUMMYFUNCTION(AUTOFILL(CONCATENATE("Repayment ",SLICE(Q1," ",2)+1),IFS($F2="bi-weekly",$A2+CEILING(('13-week CF Forecast'!$B$1-$A2)/14,1)*14+14*(COLUMN()-7),$F2="weekly",$A2+CEILING(('13-week CF Forecast'!$B$1-$A2)/7,1)*7+7*(COLUMN()-7),$F2="monthly",DATE(YEAR($A2),MONTH($A2)+CEILING(DATEDIF($A2,'13-week CF Forecast'!$B$1,"m")+1,1)+COLUMN()-7,DAY($A2)),$F2="quarterly",DATE(YEAR($A2),MONTH($A2)+3*CEILING((DATEDIF($A2,'13-week CF Forecast'!$B$1,"m")+1)/3,1)+(COLUMN()-7)*3,DAY($A2)),$F2="yearly",DATE(YEAR($A2)+CEILING((DATEDIF($A2,'13-week CF Forecast'!$B$1,"y")+1),1)+COLUMN()-7,MONTH($A2),DAY($A2)),TRUE,""),1)),"Repayment 12") -> Repayment 12 | S1: =IFERROR(ROWSDUMMYFUNCTION(AUTOFILL(CONCATENATE("Repayment ",SLICE(R1," ",2)+1),IFS($F2="bi-weekly",$A2+CEILING(('13-week CF Forecast'!$B$1-$A2)/14,1)*14+14*(COLUMN()-7),$F2="weekly",$A2+CEILING(('13-week CF Forecast'!$B$1-$A2)/7,1)*7+7*(COLUMN()-7),$F2="monthly",DATE(YEAR($A2),MONTH($A2)+CEILING(DATEDIF($A2,'13-week CF Forecast'!$B$1,"m")+1,1)+COLUMN()-7,DAY($A2)),$F2="quarterly",DATE(YEAR($A2),MONTH($A2)+3*CEILING((DATEDIF($A2,'13-week CF Forecast'!$B$1,"m")+1)/3,1)+(COLUMN()-7)*3,DAY($A2)),$F2="yearly",DATE(YEAR($A2)+CEILING((DATEDIF($A2,'13-week CF Forecast'!$B$1,"y")+1),1)+COLUMN()-7,MONTH($A2),DAY($A2)),TRUE,""),1)),"Repayment 13") -> Repayment 13 | T1: =IFERROR(ROWSDUMMYFUNCTION(AUTOFILL("Repayment Schedule",UNNEST(PAIR2JSON('Recurring Transactions'!$A$1,'Recurring Transactions'!A2,'Recurring Transactions'!$B$1,'Recurring Transactions'!B2,'Recurring Transactions'!$C$1,'Recurring Transactions'!C2,'Recurring Transactions'!$D$1,'Recurring Transactions'!D2,'Recurring Transactions'!$E$1,'Recurring Transactions'!E2,'Recurring Transactions'!$F$1,'Recurring Transactions'!F2,"Payment schedule",VALUE(RANGE2JSON('Recurring Transactions'!F2,'Recurring Transactions'!G2:S2)))),1)),"Repayment Schedule") -> Repayment Schedule | U1: Payment Method
A2: 45658 | B2: Rent | C2: Rent | D2: 10056 | E2: Overhead Expenditures | F2: monthly | G2: =IFS($F2="bi-weekly",$A2+CEILING(('13-week CF Forecast'!$B$1-$A2)/14,1)*14+14*(COLUMN()-7),$F2="weekly",$A2+CEILING(('13-week CF Forecast'!$B$1-$A2)/7,1)*7+7*(COLUMN()-7),$F2="monthly",DATE(YEAR($A2),MONTH($A2)+CEILING(DATEDIF($A2,'13-week CF Forecast'!$B$1,"m")+1,1)+COLUMN()-7,DAY($A2)),$F2="quarterly",DATE(YEAR($A2),MONTH($A2)+3*CEILING((DATEDIF($A2,'13-week CF Forecast'!$B$1,"m")+1)/3,1)+(COLUMN()-7)*3,DAY($A2)),$F2="yearly",DATE(YEAR($A2)+CEILING((DATEDIF($A2,'13-week CF Forecast'!$B$1,"y")+1),1)+COLUMN()-7,MONTH($A2),DAY($A2)),TRUE,"") -> 45839 | H2: =IFS($F2="bi-weekly",$A2+CEILING(('13-week CF Forecast'!$B$1-$A2)/14,1)*14+14*(COLUMN()-7),$F2="weekly",$A2+CEILING(('13-week CF Forecast'!$B$1-$A2)/7,1)*7+7*(COLUMN()-7),$F2="monthly",DATE(YEAR($A2),MONTH($A2)+CEILING(DATEDIF($A2,'13-week CF Forecast'!$B$1,"m")+1,1)+COLUMN()-7,DAY($A2)),$F2="quarterly",DATE(YEAR($A2),MONTH($A2)+3*CEILING((DATEDIF($A2,'13-week CF Forecast'!$B$1,"m")+1)/3,1)+(COLUMN()-7)*3,DAY($A2)),$F2="yearly",DATE(YEAR($A2)+CEILING((DATEDIF($A2,'13-week CF Forecast'!$B$1,"y")+1),1)+COLUMN()-7,MONTH($A2),DAY($A2)),TRUE,"") -> 45870 | I2: =IFS($F2="bi-weekly",$A2+CEILING(('13-week CF Forecast'!$B$1-$A2)/14,1)*14+14*(COLUMN()-7),$F2="weekly",$A2+CEILING(('13-week CF Forecast'!$B$1-$A2)/7,1)*7+7*(COLUMN()-7),$F2="monthly",DATE(YEAR($A2),MONTH($A2)+CEILING(DATEDIF($A2,'13-week CF Forecast'!$B$1,"m")+1,1)+COLUMN()-7,DAY($A2)),$F2="quarterly",DATE(YEAR($A2),MONTH($A2)+3*CEILING((DATEDIF($A2,'13-week CF Forecast'!$B$1,"m")+1)/3,1)+(COLUMN()-7)*3,DAY($A2)),$F2="yearly",DATE(YEAR($A2)+CEILING((DATEDIF($A2,'13-week CF Forecast'!$B$1,"y")+1),1)+COLUMN()-7,MONTH($A2),DAY($A2)),TRUE,"") -> 45901 | J2: =IFS($F2="bi-weekly",$A2+CEILING(('13-week CF Forecast'!$B$1-$A2)/14,1)*14+14*(COLUMN()-7),$F2="weekly",$A2+CEILING(('13-week CF Forecast'!$B$1-$A2)/7,1)*7+7*(COLUMN()-7),$F2="monthly",DATE(YEAR($A2),MONTH($A2)+CEILING(DATEDIF($A2,'13-week CF Forecast'!$B$1,"m")+1,1)+COLUMN()-7,DAY($A2)),$F2="quarterly",DATE(YEAR($A2),MONTH($A2)+3*CEILING((DATEDIF($A2,'13-week CF Forecast'!$B$1,"m")+1)/3,1)+(COLUMN()-7)*3,DAY($A2)),$F2="yearly",DATE(YEAR($A2)+CEILING((DATEDIF($A2,'13-week CF Forecast'!$B$1,"y")+1),1)+COLUMN()-7,MONTH($A2),DAY($A2)),TRUE,"") -> 45931 | K2: =IFS($F2="bi-weekly",$A2+CEILING(('13-week CF Forecast'!$B$1-$A2)/14,1)*14+14*(COLUMN()-7),$F2="weekly",$A2+CEILING(('13-week CF Forecast'!$B$1-$A2)/7,1)*7+7*(COLUMN()-7),$F2="monthly",DATE(YEAR($A2),MONTH($A2)+CEILING(DATEDIF($A2,'13-week CF Forecast'!$B$1,"m")+1,1)+COLUMN()-7,DAY($A2)),$F2="quarterly",DATE(YEAR($A2),MONTH($A2)+3*CEILING((DATEDIF($A2,'13-week CF Forecast'!$B$1,"m")+1)/3,1)+(COLUMN()-7)*3,DAY($A2)),$F2="yearly",DATE(YEAR($A2)+CEILING((DATEDIF($A2,'13-week CF Forecast'!$B$1,"y")+1),1)+COLUMN()-7,MONTH($A2),DAY($A2)),TRUE,"") -> 45962 | L2: =IFS($F2="bi-weekly",$A2+CEILING(('13-week CF Forecast'!$B$1-$A2)/14,1)*14+14*(COLUMN()-7),$F2="weekly",$A2+CEILING(('13-week CF Forecast'!$B$1-$A2)/7,1)*7+7*(COLUMN()-7),$F2="monthly",DATE(YEAR($A2),MONTH($A2)+CEILING(DATEDIF($A2,'13-week CF Forecast'!$B$1,"m")+1,1)+COLUMN()-7,DAY($A2)),$F2="quarterly",DATE(YEAR($A2),MONTH($A2)+3*CEILING((DATEDIF($A2,'13-week CF Forecast'!$B$1,"m")+1)/3,1)+(COLUMN()-7)*3,DAY($A2)),$F2="yearly",DATE(YEAR($A2)+CEILING((DATEDIF($A2,'13-week CF Forecast'!$B$1,"y")+1),1)+COLUMN()-7,MONTH($A2),DAY($A2)),TRUE,"") -> 45992 | M2: =IFS($F2="bi-weekly",$A2+CEILING(('13-week CF Forecast'!$B$1-$A2)/14,1)*14+14*(COLUMN()-7),$F2="weekly",$A2+CEILING(('13-week CF Forecast'!$B$1-$A2)/7,1)*7+7*(COLUMN()-7),$F2="monthly",DATE(YEAR($A2),MONTH($A2)+CEILING(DATEDIF($A2,'13-week CF Forecast'!$B$1,"m")+1,1)+COLUMN()-7,DAY($A2)),$F2="quarterly",DATE(YEAR($A2),MONTH($A2)+3*CEILING((DATEDIF($A2,'13-week CF Forecast'!$B$1,"m")+1)/3,1)+(COLUMN()-7)*3,DAY($A2)),$F2="yearly",DATE(YEAR($A2)+CEILING((DATEDIF($A2,'13-week CF Forecast'!$B$1,"y")+1),1)+COLUMN()-7,MONTH($A2),DAY($A2)),TRUE,"") -> 46023 | N2: =IFS($F2="bi-weekly",$A2+CEILING(('13-week CF Forecast'!$B$1-$A2)/14,1)*14+14*(COLUMN()-7),$F2="weekly",$A2+CEILING(('13-week CF Forecast'!$B$1-$A2)/7,1)*7+7*(COLUMN()-7),$F2="monthly",DATE(YEAR($A2),MONTH($A2)+CEILING(DATEDIF($A2,'13-week CF Forecast'!$B$1,"m")+1,1)+COLUMN()-7,DAY($A2)),$F2="quarterly",DATE(YEAR($A2),MONTH($A2)+3*CEILING((DATEDIF($A2,'13-week CF Forecast'!$B$1,"m")+1)/3,1)+(COLUMN()-7)*3,DAY($A2)),$F2="yearly",DATE(YEAR($A2)+CEILING((DATEDIF($A2,'13-week CF Forecast'!$B$1,"y")+1),1)+COLUMN()-7,MONTH($A2),DAY($A2)),TRUE,"") -> 46054 | ... S2: =IFS($F2="bi-weekly",$A2+CEILING(('13-week CF Forecast'!$B$1-$A2)/14,1)*14+14*(COLUMN()-7),$F2="weekly",$A2+CEILING(('13-week CF Forecast'!$B$1-$A2)/7,1)*7+7*(COLUMN()-7),$F2="monthly",DATE(YEAR($A2),MONTH($A2)+CEILING(DATEDIF($A2,'13-week CF Forecast'!$B$1,"m")+1,1)+COLUMN()-7,DAY($A2)),$F2="quarterly",DATE(YEAR($A2),MONTH($A2)+3*CEILING((DATEDIF($A2,'13-week CF Forecast'!$B$1,"m")+1)/3,1)+(COLUMN()-7)*3,DAY($A2)),$F2="yearly",DATE(YEAR($A2)+CEILING((DATEDIF($A2,'13-week CF Forecast'!$B$1,"y")+1),1)+COLUMN()-7,MONTH($A2),DAY($A2)),TRUE,"") -> 46204 | T2: =IFERROR(ROWSDUMMYFUNCTION(UNNEST(PAIR2JSON('Recurring Transactions'!$A$1,'Recurring Transactions'!A2,'Recurring Transactions'!$B$1,'Recurring Transactions'!B2,'Recurring Transactions'!$C$1,'Recurring Transactions'!C2,'Recurring Transactions'!$D$1,'Recurring Transactions'!D2,'Recurring Transactions'!$E$1,'Recurring Transactions'!E2,'Recurring Transactions'!$F$1,'Recurring Transactions'!F2,"Payment schedule",VALUE(RANGE2JSON('Recurring Transactions'!F2,'Recurring Transactions'!G2:S2))))),"[{""First payment date"":""2025-01-01"",""Counterparty"":""Rent"",""Description"":""Rent"",""Amount"":""$10056"",""Category"":""Overhead Expenditures"",""Frequency"":""monthly"",""Payment schedule_0"":""2025-07-01""},{""First payment date"":""2025-01-01"",""Counterparty"":""Rent"",""Descript"&"ion"":""Rent"",""Amount"":""$10056"",""Category"":""Overhead Expenditures"",""Frequency"":""monthly"",""Payment schedule_0"":""2025-08-01""},{""First payment date"":""2025-01-01"",""Counterparty"":""Rent"",""Description"":""Rent"",""Amount"":""$10056"",""Category"":""Overhead Expenditures"",""F"&"requency"":""monthly"",""Payment schedule_0"":""2025-09-01""},{""First payment date"":""2025-01-01"",""Counterparty"":""Rent"",""Description"":""Rent"",""Amount"":""$10056"",""Category"":""Overhead Expenditures"",""Frequency"":""monthly"",""Payment schedule_0"":""2025-10-01""},{""First paym"&"ent date"":""2025-01-01"",""Counterparty"":""Rent"",""Description"":""Rent"",""Amount"":""$10056"",""Category"":""Overhead Expenditures"",""Frequency"":""monthly"",""Payment schedule_0"":""2025-11-01""},{""First payment date"":""2025-01-01"",""Counterparty"":""Rent"",""Description"":""Rent"","""&"Amount"":""$10056"",""Category"":""Overhead Expenditures"",""Frequency"":""monthly"",""Payment schedule_0"":""2025-12-01""},{""First payment date"":""2025-01-01"",""Counterparty"":""Rent"",""Description"":""Rent"",""Amount"":""$10056"",""Category"":""Overhead Expenditures"",""Frequency"":""mo"&"nthly"",""Payment schedule_0"":""2026-01-01""},{""First payment date"":""2025-01-01"",""Counterparty"":""Rent"",""Description"":""Rent"",""Amount"":""$10056"",""Category"":""Overhead Expenditures"",""Frequency"":""monthly"",""Payment schedule_0"":""2026-02-01""},{""First payment date"":""20"&"25-01-01"",""Counterparty"":""Rent"",""Description"":""Rent"",""Amount"":""$10056"",""Category"":""Overhead Expenditures"",""Frequency"":""monthly"",""Payment schedule_0"":""2026-03-01""},{""First payment date"":""2025-01-01"",""Counterparty"":""Rent"",""Description"":""Rent"",""Amount"":""$100"&"56"",""Category"":""Overhead Expenditures"",""Frequency"":""monthly"",""Payment schedule_0"":""2026-04-01""},{""First payment date"":""2025-01-01"",""Counterparty"":""Rent"",""Description"":""Rent"",""Amount"":""$10056"",""Category"":""Overhead Expenditures"",""Frequency"":""monthly"",""Payme"&"nt schedule_0"":""2026-05-01""},{""First payment date"":""2025-01-01"",""Counterparty"":""Rent"",""Description"":""Rent"",""Amount"":""$10056"",""Category"":""Overhead Expenditures"",""Frequency"":""monthly"",""Payment schedule_0"":""2026-06-01""},{""First payment date"":""2025-01-01"",""Co"&"unterparty"":""Rent"",""Description"":""Rent"",""Amount"":""$10056"",""Category"":""Overhead Expenditures"",""Frequency"":""monthly"",""Payment schedule_0"":""2026-07-01""}]") -> [{"First payment date":"2025-01-01","Counterparty":"Rent","Description":"Rent","Amount":"$10056","Category":"Overhead Expenditures","Frequency":"monthly","Payment schedule_0":"2025-07-01"},{"First payment date":"2025-01-01","Counterparty":"Rent","Description":"Rent","Amount":"$10056","Category":"Overhead Expenditures","Frequency":"monthly","Payment schedule_0":"2025-08-01"},{"First payment date":"2025-01-01","Counterparty":"Rent","Description":"Rent","Amount":"$10056","Category":"Overhead Expenditures","Frequency":"monthly","Payment schedule_0":"2025-09-01"},{"First payment date":"2025-01-01","Counterparty":"Rent","Description":"Rent","Amount":"$10056","Category":"Overhead Expenditures","Frequency":"monthly","Payment schedule_0":"2025-10-01"},{"First payment date":"2025-01-01","Counterparty":"Rent","Description":"Rent","Amount":"$10056","Category":"Overhead Expenditures","Frequency":"monthly","Payment schedule_0":"2025-11-01"},{"First payment date":"2025-01-01","Counterparty":"Rent","Description":"Rent","Amount":"$10056","Category":"Overhead Expenditures","Frequency":"monthly","Payment schedule_0":"2025-12-01"},{"First payment date":"2025-01-01","Counterparty":"Rent","Description":"Rent","Amount":"$10056","Category":"Overhead Expenditures","Frequency":"monthly","Payment schedule_0":"2026-01-01"},{"First payment date":"2025-01-01","Counterparty":"Rent","Description":"Rent","Amount":"$10056","Category":"Overhead Expenditures","Frequency":"monthly","Payment schedule_0":"2026-02-01"},{"First payment date":"2025-01-01","Counterparty":"Rent","Description":"Rent","Amount":"$10056","Category":"Overhead Expenditures","Frequency":"monthly","Payment schedule_0":"2026-03-01"},{"First payment date":"2025-01-01","Counterparty":"Rent","Description":"Rent","Amount":"$10056","Category":"Overhead Expenditures","Frequency":"monthly","Payment schedule_0":"2026-04-01"},{"First payment date":"2025-01-01","Counterparty":"Rent","Description":"Rent","Amount":"$10056","Category":"Overhead Expenditures","Frequency":"monthly","Payment schedule_0":"2026-05-01"},{"First payment date":"2025-01-01","Counterparty":"Rent","Description":"Rent","Amount":"$10056","Category":"Overhead Expenditures","Frequency":"monthly","Payment schedule_0":"2026-06-01"},{"First payment date":"2025-01-01","Counterparty":"Rent","Description":"Rent","Amount":"$10056","Category":"Overhead Expenditures","Frequency":"monthly","Payment schedule_0":"2026-07-01"}] | U2: Staychill
A3: 45658 | B3: Sublease | C3: Sublease | D3: 3056.37 | E3: Overhead Expenditures | F3: monthly | G3: =IFS($F3="bi-weekly",$A3+CEILING(('13-week CF Forecast'!$B$1-$A3)/14,1)*14+14*(COLUMN()-7),$F3="weekly",$A3+CEILING(('13-week CF Forecast'!$B$1-$A3)/7,1)*7+7*(COLUMN()-7),$F3="monthly",DATE(YEAR($A3),MONTH($A3)+CEILING(DATEDIF($A3,'13-week CF Forecast'!$B$1,"m")+1,1)+COLUMN()-7,DAY($A3)),$F3="quarterly",DATE(YEAR($A3),MONTH($A3)+3*CEILING((DATEDIF($A3,'13-week CF Forecast'!$B$1,"m")+1)/3,1)+(COLUMN()-7)*3,DAY($A3)),$F3="yearly",DATE(YEAR($A3)+CEILING((DATEDIF($A3,'13-week CF Forecast'!$B$1,"y")+1),1)+COLUMN()-7,MONTH($A3),DAY($A3)),TRUE,"") -> 45839 | H3: =IFS($F3="bi-weekly",$A3+CEILING(('13-week CF Forecast'!$B$1-$A3)/14,1)*14+14*(COLUMN()-7),$F3="weekly",$A3+CEILING(('13-week CF Forecast'!$B$1-$A3)/7,1)*7+7*(COLUMN()-7),$F3="monthly",DATE(YEAR($A3),MONTH($A3)+CEILING(DATEDIF($A3,'13-week CF Forecast'!$B$1,"m")+1,1)+COLUMN()-7,DAY($A3)),$F3="quarterly",DATE(YEAR($A3),MONTH($A3)+3*CEILING((DATEDIF($A3,'13-week CF Forecast'!$B$1,"m")+1)/3,1)+(COLUMN()-7)*3,DAY($A3)),$F3="yearly",DATE(YEAR($A3)+CEILING((DATEDIF($A3,'13-week CF Forecast'!$B$1,"y")+1),1)+COLUMN()-7,MONTH($A3),DAY($A3)),TRUE,"") -> 45870 | I3: =IFS($F3="bi-weekly",$A3+CEILING(('13-week CF Forecast'!$B$1-$A3)/14,1)*14+14*(COLUMN()-7),$F3="weekly",$A3+CEILING(('13-week CF Forecast'!$B$1-$A3)/7,1)*7+7*(COLUMN()-7),$F3="monthly",DATE(YEAR($A3),MONTH($A3)+CEILING(DATEDIF($A3,'13-week CF Forecast'!$B$1,"m")+1,1)+COLUMN()-7,DAY($A3)),$F3="quarterly",DATE(YEAR($A3),MONTH($A3)+3*CEILING((DATEDIF($A3,'13-week CF Forecast'!$B$1,"m")+1)/3,1)+(COLUMN()-7)*3,DAY($A3)),$F3="yearly",DATE(YEAR($A3)+CEILING((DATEDIF($A3,'13-week CF Forecast'!$B$1,"y")+1),1)+COLUMN()-7,MONTH($A3),DAY($A3)),TRUE,"") -> 45901 | J3: =IFS($F3="bi-weekly",$A3+CEILING(('13-week CF Forecast'!$B$1-$A3)/14,1)*14+14*(COLUMN()-7),$F3="weekly",$A3+CEILING(('13-week CF Forecast'!$B$1-$A3)/7,1)*7+7*(COLUMN()-7),$F3="monthly",DATE(YEAR($A3),MONTH($A3)+CEILING(DATEDIF($A3,'13-week CF Forecast'!$B$1,"m")+1,1)+COLUMN()-7,DAY($A3)),$F3="quarterly",DATE(YEAR($A3),MONTH($A3)+3*CEILING((DATEDIF($A3,'13-week CF Forecast'!$B$1,"m")+1)/3,1)+(COLUMN()-7)*3,DAY($A3)),$F3="yearly",DATE(YEAR($A3)+CEILING((DATEDIF($A3,'13-week CF Forecast'!$B$1,"y")+1),1)+COLUMN()-7,MONTH($A3),DAY($A3)),TRUE,"") -> 45931 | K3: =IFS($F3="bi-weekly",$A3+CEILING(('13-week CF Forecast'!$B$1-$A3)/14,1)*14+14*(COLUMN()-7),$F3="weekly",$A3+CEILING(('13-week CF Forecast'!$B$1-$A3)/7,1)*7+7*(COLUMN()-7),$F3="monthly",DATE(YEAR($A3),MONTH($A3)+CEILING(DATEDIF($A3,'13-week CF Forecast'!$B$1,"m")+1,1)+COLUMN()-7,DAY($A3)),$F3="quarterly",DATE(YEAR($A3),MONTH($A3)+3*CEILING((DATEDIF($A3,'13-week CF Forecast'!$B$1,"m")+1)/3,1)+(COLUMN()-7)*3,DAY($A3)),$F3="yearly",DATE(YEAR($A3)+CEILING((DATEDIF($A3,'13-week CF Forecast'!$B$1,"y")+1),1)+COLUMN()-7,MONTH($A3),DAY($A3)),TRUE,"") -> 45962 | L3: =IFS($F3="bi-weekly",$A3+CEILING(('13-week CF Forecast'!$B$1-$A3)/14,1)*14+14*(COLUMN()-7),$F3="weekly",$A3+CEILING(('13-week CF Forecast'!$B$1-$A3)/7,1)*7+7*(COLUMN()-7),$F3="monthly",DATE(YEAR($A3),MONTH($A3)+CEILING(DATEDIF($A3,'13-week CF Forecast'!$B$1,"m")+1,1)+COLUMN()-7,DAY($A3)),$F3="quarterly",DATE(YEAR($A3),MONTH($A3)+3*CEILING((DATEDIF($A3,'13-week CF Forecast'!$B$1,"m")+1)/3,1)+(COLUMN()-7)*3,DAY($A3)),$F3="yearly",DATE(YEAR($A3)+CEILING((DATEDIF($A3,'13-week CF Forecast'!$B$1,"y")+1),1)+COLUMN()-7,MONTH($A3),DAY($A3)),TRUE,"") -> 45992 | M3: =IFS($F3="bi-weekly",$A3+CEILING(('13-week CF Forecast'!$B$1-$A3)/14,1)*14+14*(COLUMN()-7),$F3="weekly",$A3+CEILING(('13-week CF Forecast'!$B$1-$A3)/7,1)*7+7*(COLUMN()-7),$F3="monthly",DATE(YEAR($A3),MONTH($A3)+CEILING(DATEDIF($A3,'13-week CF Forecast'!$B$1,"m")+1,1)+COLUMN()-7,DAY($A3)),$F3="quarterly",DATE(YEAR($A3),MONTH($A3)+3*CEILING((DATEDIF($A3,'13-week CF Forecast'!$B$1,"m")+1)/3,1)+(COLUMN()-7)*3,DAY($A3)),$F3="yearly",DATE(YEAR($A3)+CEILING((DATEDIF($A3,'13-week CF Forecast'!$B$1,"y")+1),1)+COLUMN()-7,MONTH($A3),DAY($A3)),TRUE,"") -> 46023 | N3: =IFS($F3="bi-weekly",$A3+CEILING(('13-week CF Forecast'!$B$1-$A3)/14,1)*14+14*(COLUMN()-7),$F3="weekly",$A3+CEILING(('13-week CF Forecast'!$B$1-$A3)/7,1)*7+7*(COLUMN()-7),$F3="monthly",DATE(YEAR($A3),MONTH($A3)+CEILING(DATEDIF($A3,'13-week CF Forecast'!$B$1,"m")+1,1)+COLUMN()-7,DAY($A3)),$F3="quarterly",DATE(YEAR($A3),MONTH($A3)+3*CEILING((DATEDIF($A3,'13-week CF Forecast'!$B$1,"m")+1)/3,1)+(COLUMN()-7)*3,DAY($A3)),$F3="yearly",DATE(YEAR($A3)+CEILING((DATEDIF($A3,'13-week CF Forecast'!$B$1,"y")+1),1)+COLUMN()-7,MONTH($A3),DAY($A3)),TRUE,"") -> 46054 | ... S3: =IFS($F3="bi-weekly",$A3+CEILING(('13-week CF Forecast'!$B$1-$A3)/14,1)*14+14*(COLUMN()-7),$F3="weekly",$A3+CEILING(('13-week CF Forecast'!$B$1-$A3)/7,1)*7+7*(COLUMN()-7),$F3="monthly",DATE(YEAR($A3),MONTH($A3)+CEILING(DATEDIF($A3,'13-week CF Forecast'!$B$1,"m")+1,1)+COLUMN()-7,DAY($A3)),$F3="quarterly",DATE(YEAR($A3),MONTH($A3)+3*CEILING((DATEDIF($A3,'13-week CF Forecast'!$B$1,"m")+1)/3,1)+(COLUMN()-7)*3,DAY($A3)),$F3="yearly",DATE(YEAR($A3)+CEILING((DATEDIF($A3,'13-week CF Forecast'!$B$1,"y")+1),1)+COLUMN()-7,MONTH($A3),DAY($A3)),TRUE,"") -> 46204 | T3: =IFERROR(ROWSDUMMYFUNCTION(UNNEST(PAIR2JSON('Recurring Transactions'!$A$1,'Recurring Transactions'!A3,'Recurring Transactions'!$B$1,'Recurring Transactions'!B3,'Recurring Transactions'!$C$1,'Recurring Transactions'!C3,'Recurring Transactions'!$D$1,'Recurring Transactions'!D3,'Recurring Transactions'!$E$1,'Recurring Transactions'!E3,'Recurring Transactions'!$F$1,'Recurring Transactions'!F3,"Payment schedule",VALUE(RANGE2JSON('Recurring Transactions'!F3,'Recurring Transactions'!G3:S3))))),"[{""First payment date"":""2025-01-01"",""Counterparty"":""Sublease"",""Description"":""Sublease"",""Amount"":""$3056.37"",""Category"":""Overhead Expenditures"",""Frequency"":""monthly"",""Payment schedule_0"":""2025-07-01""},{""First payment date"":""2025-01-01"",""Counterparty"":""Suble"&"ase"",""Description"":""Sublease"",""Amount"":""$3056.37"",""Category"":""Overhead Expenditures"",""Frequency"":""monthly"",""Payment schedule_0"":""2025-08-01""},{""First payment date"":""2025-01-01"",""Counterparty"":""Sublease"",""Description"":""Sublease"",""Amount"":""$3056.37"",""Catego"&"ry"":""Overhead Expenditures"",""Frequency"":""monthly"",""Payment schedule_0"":""2025-09-01""},{""First payment date"":""2025-01-01"",""Counterparty"":""Sublease"",""Description"":""Sublease"",""Amount"":""$3056.37"",""Category"":""Overhead Expenditures"",""Frequency"":""monthly"",""Paymen"&"t schedule_0"":""2025-10-01""},{""First payment date"":""2025-01-01"",""Counterparty"":""Sublease"",""Description"":""Sublease"",""Amount"":""$3056.37"",""Category"":""Overhead Expenditures"",""Frequency"":""monthly"",""Payment schedule_0"":""2025-11-01""},{""First payment date"":""2025-0"&"1-01"",""Counterparty"":""Sublease"",""Description"":""Sublease"",""Amount"":""$3056.37"",""Category"":""Overhead Expenditures"",""Frequency"":""monthly"",""Payment schedule_0"":""2025-12-01""},{""First payment date"":""2025-01-01"",""Counterparty"":""Sublease"",""Description"":""Sublease"","&"""Amount"":""$3056.37"",""Category"":""Overhead Expenditures"",""Frequency"":""monthly"",""Payment schedule_0"":""2026-01-01""},{""First payment date"":""2025-01-01"",""Counterparty"":""Sublease"",""Description"":""Sublease"",""Amount"":""$3056.37"",""Category"":""Overhead Expenditures"",""F"&"requency"":""monthly"",""Payment schedule_0"":""2026-02-01""},{""First payment date"":""2025-01-01"",""Counterparty"":""Sublease"",""Description"":""Sublease"",""Amount"":""$3056.37"",""Category"":""Overhead Expenditures"",""Frequency"":""monthly"",""Payment schedule_0"":""2026-03-01""},{"""&"First payment date"":""2025-01-01"",""Counterparty"":""Sublease"",""Description"":""Sublease"",""Amount"":""$3056.37"",""Category"":""Overhead Expenditures"",""Frequency"":""monthly"",""Payment schedule_0"":""2026-04-01""},{""First payment date"":""2025-01-01"",""Counterparty"":""Sublease"&""",""Description"":""Sublease"",""Amount"":""$3056.37"",""Category"":""Overhead Expenditures"",""Frequency"":""monthly"",""Payment schedule_0"":""2026-05-01""},{""First payment date"":""2025-01-01"",""Counterparty"":""Sublease"",""Description"":""Sublease"",""Amount"":""$3056.37"",""Category"""&":""Overhead Expenditures"",""Frequency"":""monthly"",""Payment schedule_0"":""2026-06-01""},{""First payment date"":""2025-01-01"",""Counterparty"":""Sublease"",""Description"":""Sublease"",""Amount"":""$3056.37"",""Category"":""Overhead Expenditures"",""Frequency"":""monthly"",""Payment s"&"chedule_0"":""2026-07-01""}]") -> [{"First payment date":"2025-01-01","Counterparty":"Sublease","Description":"Sublease","Amount":"$3056.37","Category":"Overhead Expenditures","Frequency":"monthly","Payment schedule_0":"2025-07-01"},{"First payment date":"2025-01-01","Counterparty":"Sublease","Description":"Sublease","Amount":"$3056.37","Category":"Overhead Expenditures","Frequency":"monthly","Payment schedule_0":"2025-08-01"},{"First payment date":"2025-01-01","Counterparty":"Sublease","Description":"Sublease","Amount":"$3056.37","Category":"Overhead Expenditures","Frequency":"monthly","Payment schedule_0":"2025-09-01"},{"First payment date":"2025-01-01","Counterparty":"Sublease","Description":"Sublease","Amount":"$3056.37","Category":"Overhead Expenditures","Frequency":"monthly","Payment schedule_0":"2025-10-01"},{"First payment date":"2025-01-01","Counterparty":"Sublease","Description":"Sublease","Amount":"$3056.37","Category":"Overhead Expenditures","Frequency":"monthly","Payment schedule_0":"2025-11-01"},{"First payment date":"2025-01-01","Counterparty":"Sublease","Description":"Sublease","Amount":"$3056.37","Category":"Overhead Expenditures","Frequency":"monthly","Payment schedule_0":"2025-12-01"},{"First payment date":"2025-01-01","Counterparty":"Sublease","Description":"Sublease","Amount":"$3056.37","Category":"Overhead Expenditures","Frequency":"monthly","Payment schedule_0":"2026-01-01"},{"First payment date":"2025-01-01","Counterparty":"Sublease","Description":"Sublease","Amount":"$3056.37","Category":"Overhead Expenditures","Frequency":"monthly","Payment schedule_0":"2026-02-01"},{"First payment date":"2025-01-01","Counterparty":"Sublease","Description":"Sublease","Amount":"$3056.37","Category":"Overhead Expenditures","Frequency":"monthly","Payment schedule_0":"2026-03-01"},{"First payment date":"2025-01-01","Counterparty":"Sublease","Description":"Sublease","Amount":"$3056.37","Category":"Overhead Expenditures","Frequency":"monthly","Payment schedule_0":"2026-04-01"},{"First payment date":"2025-01-01","Counterparty":"Sublease","Description":"Sublease","Amount":"$3056.37","Category":"Overhead Expenditures","Frequency":"monthly","Payment schedule_0":"2026-05-01"},{"First payment date":"2025-01-01","Counterparty":"Sublease","Description":"Sublease","Amount":"$3056.37","Category":"Overhead Expenditures","Frequency":"monthly","Payment schedule_0":"2026-06-01"},{"First payment date":"2025-01-01","Counterparty":"Sublease","Description":"Sublease","Amount":"$3056.37","Category":"Overhead Expenditures","Frequency":"monthly","Payment schedule_0":"2026-07-01"}] | U3: Staychill
A4: 45658 | B4: Dalton | C4: Dalton | D4: 5000 | E4: Overhead Expenditures | F4: monthly | G4: =IFS($F4="bi-weekly",$A4+CEILING(('13-week CF Forecast'!$B$1-$A4)/14,1)*14+14*(COLUMN()-7),$F4="weekly",$A4+CEILING(('13-week CF Forecast'!$B$1-$A4)/7,1)*7+7*(COLUMN()-7),$F4="monthly",DATE(YEAR($A4),MONTH($A4)+CEILING(DATEDIF($A4,'13-week CF Forecast'!$B$1,"m")+1,1)+COLUMN()-7,DAY($A4)),$F4="quarterly",DATE(YEAR($A4),MONTH($A4)+3*CEILING((DATEDIF($A4,'13-week CF Forecast'!$B$1,"m")+1)/3,1)+(COLUMN()-7)*3,DAY($A4)),$F4="yearly",DATE(YEAR($A4)+CEILING((DATEDIF($A4,'13-week CF Forecast'!$B$1,"y")+1),1)+COLUMN()-7,MONTH($A4),DAY($A4)),TRUE,"") -> 45839 | H4: =IFS($F4="bi-weekly",$A4+CEILING(('13-week CF Forecast'!$B$1-$A4)/14,1)*14+14*(COLUMN()-7),$F4="weekly",$A4+CEILING(('13-week CF Forecast'!$B$1-$A4)/7,1)*7+7*(COLUMN()-7),$F4="monthly",DATE(YEAR($A4),MONTH($A4)+CEILING(DATEDIF($A4,'13-week CF Forecast'!$B$1,"m")+1,1)+COLUMN()-7,DAY($A4)),$F4="quarterly",DATE(YEAR($A4),MONTH($A4)+3*CEILING((DATEDIF($A4,'13-week CF Forecast'!$B$1,"m")+1)/3,1)+(COLUMN()-7)*3,DAY($A4)),$F4="yearly",DATE(YEAR($A4)+CEILING((DATEDIF($A4,'13-week CF Forecast'!$B$1,"y")+1),1)+COLUMN()-7,MONTH($A4),DAY($A4)),TRUE,"") -> 45870 | I4: =IFS($F4="bi-weekly",$A4+CEILING(('13-week CF Forecast'!$B$1-$A4)/14,1)*14+14*(COLUMN()-7),$F4="weekly",$A4+CEILING(('13-week CF Forecast'!$B$1-$A4)/7,1)*7+7*(COLUMN()-7),$F4="monthly",DATE(YEAR($A4),MONTH($A4)+CEILING(DATEDIF($A4,'13-week CF Forecast'!$B$1,"m")+1,1)+COLUMN()-7,DAY($A4)),$F4="quarterly",DATE(YEAR($A4),MONTH($A4)+3*CEILING((DATEDIF($A4,'13-week CF Forecast'!$B$1,"m")+1)/3,1)+(COLUMN()-7)*3,DAY($A4)),$F4="yearly",DATE(YEAR($A4)+CEILING((DATEDIF($A4,'13-week CF Forecast'!$B$1,"y")+1),1)+COLUMN()-7,MONTH($A4),DAY($A4)),TRUE,"") -> 45901 | J4: =IFS($F4="bi-weekly",$A4+CEILING(('13-week CF Forecast'!$B$1-$A4)/14,1)*14+14*(COLUMN()-7),$F4="weekly",$A4+CEILING(('13-week CF Forecast'!$B$1-$A4)/7,1)*7+7*(COLUMN()-7),$F4="monthly",DATE(YEAR($A4),MONTH($A4)+CEILING(DATEDIF($A4,'13-week CF Forecast'!$B$1,"m")+1,1)+COLUMN()-7,DAY($A4)),$F4="quarterly",DATE(YEAR($A4),MONTH($A4)+3*CEILING((DATEDIF($A4,'13-week CF Forecast'!$B$1,"m")+1)/3,1)+(COLUMN()-7)*3,DAY($A4)),$F4="yearly",DATE(YEAR($A4)+CEILING((DATEDIF($A4,'13-week CF Forecast'!$B$1,"y")+1),1)+COLUMN()-7,MONTH($A4),DAY($A4)),TRUE,"") -> 45931 | K4: =IFS($F4="bi-weekly",$A4+CEILING(('13-week CF Forecast'!$B$1-$A4)/14,1)*14+14*(COLUMN()-7),$F4="weekly",$A4+CEILING(('13-week CF Forecast'!$B$1-$A4)/7,1)*7+7*(COLUMN()-7),$F4="monthly",DATE(YEAR($A4),MONTH($A4)+CEILING(DATEDIF($A4,'13-week CF Forecast'!$B$1,"m")+1,1)+COLUMN()-7,DAY($A4)),$F4="quarterly",DATE(YEAR($A4),MONTH($A4)+3*CEILING((DATEDIF($A4,'13-week CF Forecast'!$B$1,"m")+1)/3,1)+(COLUMN()-7)*3,DAY($A4)),$F4="yearly",DATE(YEAR($A4)+CEILING((DATEDIF($A4,'13-week CF Forecast'!$B$1,"y")+1),1)+COLUMN()-7,MONTH($A4),DAY($A4)),TRUE,"") -> 45962 | L4: =IFS($F4="bi-weekly",$A4+CEILING(('13-week CF Forecast'!$B$1-$A4)/14,1)*14+14*(COLUMN()-7),$F4="weekly",$A4+CEILING(('13-week CF Forecast'!$B$1-$A4)/7,1)*7+7*(COLUMN()-7),$F4="monthly",DATE(YEAR($A4),MONTH($A4)+CEILING(DATEDIF($A4,'13-week CF Forecast'!$B$1,"m")+1,1)+COLUMN()-7,DAY($A4)),$F4="quarterly",DATE(YEAR($A4),MONTH($A4)+3*CEILING((DATEDIF($A4,'13-week CF Forecast'!$B$1,"m")+1)/3,1)+(COLUMN()-7)*3,DAY($A4)),$F4="yearly",DATE(YEAR($A4)+CEILING((DATEDIF($A4,'13-week CF Forecast'!$B$1,"y")+1),1)+COLUMN()-7,MONTH($A4),DAY($A4)),TRUE,"") -> 45992 | M4: =IFS($F4="bi-weekly",$A4+CEILING(('13-week CF Forecast'!$B$1-$A4)/14,1)*14+14*(COLUMN()-7),$F4="weekly",$A4+CEILING(('13-week CF Forecast'!$B$1-$A4)/7,1)*7+7*(COLUMN()-7),$F4="monthly",DATE(YEAR($A4),MONTH($A4)+CEILING(DATEDIF($A4,'13-week CF Forecast'!$B$1,"m")+1,1)+COLUMN()-7,DAY($A4)),$F4="quarterly",DATE(YEAR($A4),MONTH($A4)+3*CEILING((DATEDIF($A4,'13-week CF Forecast'!$B$1,"m")+1)/3,1)+(COLUMN()-7)*3,DAY($A4)),$F4="yearly",DATE(YEAR($A4)+CEILING((DATEDIF($A4,'13-week CF Forecast'!$B$1,"y")+1),1)+COLUMN()-7,MONTH($A4),DAY($A4)),TRUE,"") -> 46023 | N4: =IFS($F4="bi-weekly",$A4+CEILING(('13-week CF Forecast'!$B$1-$A4)/14,1)*14+14*(COLUMN()-7),$F4="weekly",$A4+CEILING(('13-week CF Forecast'!$B$1-$A4)/7,1)*7+7*(COLUMN()-7),$F4="monthly",DATE(YEAR($A4),MONTH($A4)+CEILING(DATEDIF($A4,'13-week CF Forecast'!$B$1,"m")+1,1)+COLUMN()-7,DAY($A4)),$F4="quarterly",DATE(YEAR($A4),MONTH($A4)+3*CEILING((DATEDIF($A4,'13-week CF Forecast'!$B$1,"m")+1)/3,1)+(COLUMN()-7)*3,DAY($A4)),$F4="yearly",DATE(YEAR($A4)+CEILING((DATEDIF($A4,'13-week CF Forecast'!$B$1,"y")+1),1)+COLUMN()-7,MONTH($A4),DAY($A4)),TRUE,"") -> 46054 | ... S4: =IFS($F4="bi-weekly",$A4+CEILING(('13-week CF Forecast'!$B$1-$A4)/14,1)*14+14*(COLUMN()-7),$F4="weekly",$A4+CEILING(('13-week CF Forecast'!$B$1-$A4)/7,1)*7+7*(COLUMN()-7),$F4="monthly",DATE(YEAR($A4),MONTH($A4)+CEILING(DATEDIF($A4,'13-week CF Forecast'!$B$1,"m")+1,1)+COLUMN()-7,DAY($A4)),$F4="quarterly",DATE(YEAR($A4),MONTH($A4)+3*CEILING((DATEDIF($A4,'13-week CF Forecast'!$B$1,"m")+1)/3,1)+(COLUMN()-7)*3,DAY($A4)),$F4="yearly",DATE(YEAR($A4)+CEILING((DATEDIF($A4,'13-week CF Forecast'!$B$1,"y")+1),1)+COLUMN()-7,MONTH($A4),DAY($A4)),TRUE,"") -> 46204 | T4: =IFERROR(ROWSDUMMYFUNCTION(UNNEST(PAIR2JSON('Recurring Transactions'!$A$1,'Recurring Transactions'!A4,'Recurring Transactions'!$B$1,'Recurring Transactions'!B4,'Recurring Transactions'!$C$1,'Recurring Transactions'!C4,'Recurring Transactions'!$D$1,'Recurring Transactions'!D4,'Recurring Transactions'!$E$1,'Recurring Transactions'!E4,'Recurring Transactions'!$F$1,'Recurring Transactions'!F4,"Payment schedule",VALUE(RANGE2JSON('Recurring Transactions'!F4,'Recurring Transactions'!G4:S4))))),"[{""First payment date"":""2025-01-01"",""Counterparty"":""Dalton"",""Description"":""Dalton"",""Amount"":""$5000"",""Category"":""Overhead Expenditures"",""Frequency"":""monthly"",""Payment schedule_0"":""2025-07-01""},{""First payment date"":""2025-01-01"",""Counterparty"":""Dalton"",""Des"&"cription"":""Dalton"",""Amount"":""$5000"",""Category"":""Overhead Expenditures"",""Frequency"":""monthly"",""Payment schedule_0"":""2025-08-01""},{""First payment date"":""2025-01-01"",""Counterparty"":""Dalton"",""Description"":""Dalton"",""Amount"":""$5000"",""Category"":""Overhead Expendi"&"tures"",""Frequency"":""monthly"",""Payment schedule_0"":""2025-09-01""},{""First payment date"":""2025-01-01"",""Counterparty"":""Dalton"",""Description"":""Dalton"",""Amount"":""$5000"",""Category"":""Overhead Expenditures"",""Frequency"":""monthly"",""Payment schedule_0"":""2025-10-01""},"&"{""First payment date"":""2025-01-01"",""Counterparty"":""Dalton"",""Description"":""Dalton"",""Amount"":""$5000"",""Category"":""Overhead Expenditures"",""Frequency"":""monthly"",""Payment schedule_0"":""2025-11-01""},{""First payment date"":""2025-01-01"",""Counterparty"":""Dalton"",""Desc"&"ription"":""Dalton"",""Amount"":""$5000"",""Category"":""Overhead Expenditures"",""Frequency"":""monthly"",""Payment schedule_0"":""2025-12-01""},{""First payment date"":""2025-01-01"",""Counterparty"":""Dalton"",""Description"":""Dalton"",""Amount"":""$5000"",""Category"":""Overhead Expendit"&"ures"",""Frequency"":""monthly"",""Payment schedule_0"":""2026-01-01""},{""First payment date"":""2025-01-01"",""Counterparty"":""Dalton"",""Description"":""Dalton"",""Amount"":""$5000"",""Category"":""Overhead Expenditures"",""Frequency"":""monthly"",""Payment schedule_0"":""2026-02-01""},{"&"""First payment date"":""2025-01-01"",""Counterparty"":""Dalton"",""Description"":""Dalton"",""Amount"":""$5000"",""Category"":""Overhead Expenditures"",""Frequency"":""monthly"",""Payment schedule_0"":""2026-03-01""},{""First payment date"":""2025-01-01"",""Counterparty"":""Dalton"",""Descr"&"iption"":""Dalton"",""Amount"":""$5000"",""Category"":""Overhead Expenditures"",""Frequency"":""monthly"",""Payment schedule_0"":""2026-04-01""},{""First payment date"":""2025-01-01"",""Counterparty"":""Dalton"",""Description"":""Dalton"",""Amount"":""$5000"",""Category"":""Overhead Expenditu"&"res"",""Frequency"":""monthly"",""Payment schedule_0"":""2026-05-01""},{""First payment date"":""2025-01-01"",""Counterparty"":""Dalton"",""Description"":""Dalton"",""Amount"":""$5000"",""Category"":""Overhead Expenditures"",""Frequency"":""monthly"",""Payment schedule_0"":""2026-06-01""},{"""&"First payment date"":""2025-01-01"",""Counterparty"":""Dalton"",""Description"":""Dalton"",""Amount"":""$5000"",""Category"":""Overhead Expenditures"",""Frequency"":""monthly"",""Payment schedule_0"":""2026-07-01""}]") -> [{"First payment date":"2025-01-01","Counterparty":"Dalton","Description":"Dalton","Amount":"$5000","Category":"Overhead Expenditures","Frequency":"monthly","Payment schedule_0":"2025-07-01"},{"First payment date":"2025-01-01","Counterparty":"Dalton","Description":"Dalton","Amount":"$5000","Category":"Overhead Expenditures","Frequency":"monthly","Payment schedule_0":"2025-08-01"},{"First payment date":"2025-01-01","Counterparty":"Dalton","Description":"Dalton","Amount":"$5000","Category":"Overhead Expenditures","Frequency":"monthly","Payment schedule_0":"2025-09-01"},{"First payment date":"2025-01-01","Counterparty":"Dalton","Description":"Dalton","Amount":"$5000","Category":"Overhead Expenditures","Frequency":"monthly","Payment schedule_0":"2025-10-01"},{"First payment date":"2025-01-01","Counterparty":"Dalton","Description":"Dalton","Amount":"$5000","Category":"Overhead Expenditures","Frequency":"monthly","Payment schedule_0":"2025-11-01"},{"First payment date":"2025-01-01","Counterparty":"Dalton","Description":"Dalton","Amount":"$5000","Category":"Overhead Expenditures","Frequency":"monthly","Payment schedule_0":"2025-12-01"},{"First payment date":"2025-01-01","Counterparty":"Dalton","Description":"Dalton","Amount":"$5000","Category":"Overhead Expenditures","Frequency":"monthly","Payment schedule_0":"2026-01-01"},{"First payment date":"2025-01-01","Counterparty":"Dalton","Description":"Dalton","Amount":"$5000","Category":"Overhead Expenditures","Frequency":"monthly","Payment schedule_0":"2026-02-01"},{"First payment date":"2025-01-01","Counterparty":"Dalton","Description":"Dalton","Amount":"$5000","Category":"Overhead Expenditures","Frequency":"monthly","Payment schedule_0":"2026-03-01"},{"First payment date":"2025-01-01","Counterparty":"Dalton","Description":"Dalton","Amount":"$5000","Category":"Overhead Expenditures","Frequency":"monthly","Payment schedule_0":"2026-04-01"},{"First payment date":"2025-01-01","Counterparty":"Dalton","Description":"Dalton","Amount":"$5000","Category":"Overhead Expenditures","Frequency":"monthly","Payment schedule_0":"2026-05-01"},{"First payment date":"2025-01-01","Counterparty":"Dalton","Description":"Dalton","Amount":"$5000","Category":"Overhead Expenditures","Frequency":"monthly","Payment schedule_0":"2026-06-01"},{"First payment date":"2025-01-01","Counterparty":"Dalton","Description":"Dalton","Amount":"$5000","Category":"Overhead Expenditures","Frequency":"monthly","Payment schedule_0":"2026-07-01"}] | U4: Chase Inc
A5: 45658 | B5: Carrigan | C5: Carrigan | D5: 3500 | E5: Sales&Marketing Expenditures | F5: monthly | G5: =IFS($F5="bi-weekly",$A5+CEILING(('13-week CF Forecast'!$B$1-$A5)/14,1)*14+14*(COLUMN()-7),$F5="weekly",$A5+CEILING(('13-week CF Forecast'!$B$1-$A5)/7,1)*7+7*(COLUMN()-7),$F5="monthly",DATE(YEAR($A5),MONTH($A5)+CEILING(DATEDIF($A5,'13-week CF Forecast'!$B$1,"m")+1,1)+COLUMN()-7,DAY($A5)),$F5="quarterly",DATE(YEAR($A5),MONTH($A5)+3*CEILING((DATEDIF($A5,'13-week CF Forecast'!$B$1,"m")+1)/3,1)+(COLUMN()-7)*3,DAY($A5)),$F5="yearly",DATE(YEAR($A5)+CEILING((DATEDIF($A5,'13-week CF Forecast'!$B$1,"y")+1),1)+COLUMN()-7,MONTH($A5),DAY($A5)),TRUE,"") -> 45839 | H5: =IFS($F5="bi-weekly",$A5+CEILING(('13-week CF Forecast'!$B$1-$A5)/14,1)*14+14*(COLUMN()-7),$F5="weekly",$A5+CEILING(('13-week CF Forecast'!$B$1-$A5)/7,1)*7+7*(COLUMN()-7),$F5="monthly",DATE(YEAR($A5),MONTH($A5)+CEILING(DATEDIF($A5,'13-week CF Forecast'!$B$1,"m")+1,1)+COLUMN()-7,DAY($A5)),$F5="quarterly",DATE(YEAR($A5),MONTH($A5)+3*CEILING((DATEDIF($A5,'13-week CF Forecast'!$B$1,"m")+1)/3,1)+(COLUMN()-7)*3,DAY($A5)),$F5="yearly",DATE(YEAR($A5)+CEILING((DATEDIF($A5,'13-week CF Forecast'!$B$1,"y")+1),1)+COLUMN()-7,MONTH($A5),DAY($A5)),TRUE,"") -> 45870 | I5: =IFS($F5="bi-weekly",$A5+CEILING(('13-week CF Forecast'!$B$1-$A5)/14,1)*14+14*(COLUMN()-7),$F5="weekly",$A5+CEILING(('13-week CF Forecast'!$B$1-$A5)/7,1)*7+7*(COLUMN()-7),$F5="monthly",DATE(YEAR($A5),MONTH($A5)+CEILING(DATEDIF($A5,'13-week CF Forecast'!$B$1,"m")+1,1)+COLUMN()-7,DAY($A5)),$F5="quarterly",DATE(YEAR($A5),MONTH($A5)+3*CEILING((DATEDIF($A5,'13-week CF Forecast'!$B$1,"m")+1)/3,1)+(COLUMN()-7)*3,DAY($A5)),$F5="yearly",DATE(YEAR($A5)+CEILING((DATEDIF($A5,'13-week CF Forecast'!$B$1,"y")+1),1)+COLUMN()-7,MONTH($A5),DAY($A5)),TRUE,"") -> 45901 | J5: =IFS($F5="bi-weekly",$A5+CEILING(('13-week CF Forecast'!$B$1-$A5)/14,1)*14+14*(COLUMN()-7),$F5="weekly",$A5+CEILING(('13-week CF Forecast'!$B$1-$A5)/7,1)*7+7*(COLUMN()-7),$F5="monthly",DATE(YEAR($A5),MONTH($A5)+CEILING(DATEDIF($A5,'13-week CF Forecast'!$B$1,"m")+1,1)+COLUMN()-7,DAY($A5)),$F5="quarterly",DATE(YEAR($A5),MONTH($A5)+3*CEILING((DATEDIF($A5,'13-week CF Forecast'!$B$1,"m")+1)/3,1)+(COLUMN()-7)*3,DAY($A5)),$F5="yearly",DATE(YEAR($A5)+CEILING((DATEDIF($A5,'13-week CF Forecast'!$B$1,"y")+1),1)+COLUMN()-7,MONTH($A5),DAY($A5)),TRUE,"") -> 45931 | K5: =IFS($F5="bi-weekly",$A5+CEILING(('13-week CF Forecast'!$B$1-$A5)/14,1)*14+14*(COLUMN()-7),$F5="weekly",$A5+CEILING(('13-week CF Forecast'!$B$1-$A5)/7,1)*7+7*(COLUMN()-7),$F5="monthly",DATE(YEAR($A5),MONTH($A5)+CEILING(DATEDIF($A5,'13-week CF Forecast'!$B$1,"m")+1,1)+COLUMN()-7,DAY($A5)),$F5="quarterly",DATE(YEAR($A5),MONTH($A5)+3*CEILING((DATEDIF($A5,'13-week CF Forecast'!$B$1,"m")+1)/3,1)+(COLUMN()-7)*3,DAY($A5)),$F5="yearly",DATE(YEAR($A5)+CEILING((DATEDIF($A5,'13-week CF Forecast'!$B$1,"y")+1),1)+COLUMN()-7,MONTH($A5),DAY($A5)),TRUE,"") -> 45962 | L5: =IFS($F5="bi-weekly",$A5+CEILING(('13-week CF Forecast'!$B$1-$A5)/14,1)*14+14*(COLUMN()-7),$F5="weekly",$A5+CEILING(('13-week CF Forecast'!$B$1-$A5)/7,1)*7+7*(COLUMN()-7),$F5="monthly",DATE(YEAR($A5),MONTH($A5)+CEILING(DATEDIF($A5,'13-week CF Forecast'!$B$1,"m")+1,1)+COLUMN()-7,DAY($A5)),$F5="quarterly",DATE(YEAR($A5),MONTH($A5)+3*CEILING((DATEDIF($A5,'13-week CF Forecast'!$B$1,"m")+1)/3,1)+(COLUMN()-7)*3,DAY($A5)),$F5="yearly",DATE(YEAR($A5)+CEILING((DATEDIF($A5,'13-week CF Forecast'!$B$1,"y")+1),1)+COLUMN()-7,MONTH($A5),DAY($A5)),TRUE,"") -> 45992 | M5: =IFS($F5="bi-weekly",$A5+CEILING(('13-week CF Forecast'!$B$1-$A5)/14,1)*14+14*(COLUMN()-7),$F5="weekly",$A5+CEILING(('13-week CF Forecast'!$B$1-$A5)/7,1)*7+7*(COLUMN()-7),$F5="monthly",DATE(YEAR($A5),MONTH($A5)+CEILING(DATEDIF($A5,'13-week CF Forecast'!$B$1,"m")+1,1)+COLUMN()-7,DAY($A5)),$F5="quarterly",DATE(YEAR($A5),MONTH($A5)+3*CEILING((DATEDIF($A5,'13-week CF Forecast'!$B$1,"m")+1)/3,1)+(COLUMN()-7)*3,DAY($A5)),$F5="yearly",DATE(YEAR($A5)+CEILING((DATEDIF($A5,'13-week CF Forecast'!$B$1,"y")+1),1)+COLUMN()-7,MONTH($A5),DAY($A5)),TRUE,"") -> 46023 | N5: =IFS($F5="bi-weekly",$A5+CEILING(('13-week CF Forecast'!$B$1-$A5)/14,1)*14+14*(COLUMN()-7),$F5="weekly",$A5+CEILING(('13-week CF Forecast'!$B$1-$A5)/7,1)*7+7*(COLUMN()-7),$F5="monthly",DATE(YEAR($A5),MONTH($A5)+CEILING(DATEDIF($A5,'13-week CF Forecast'!$B$1,"m")+1,1)+COLUMN()-7,DAY($A5)),$F5="quarterly",DATE(YEAR($A5),MONTH($A5)+3*CEILING((DATEDIF($A5,'13-week CF Forecast'!$B$1,"m")+1)/3,1)+(COLUMN()-7)*3,DAY($A5)),$F5="yearly",DATE(YEAR($A5)+CEILING((DATEDIF($A5,'13-week CF Forecast'!$B$1,"y")+1),1)+COLUMN()-7,MONTH($A5),DAY($A5)),TRUE,"") -> 46054 | ... S5: =IFS($F5="bi-weekly",$A5+CEILING(('13-week CF Forecast'!$B$1-$A5)/14,1)*14+14*(COLUMN()-7),$F5="weekly",$A5+CEILING(('13-week CF Forecast'!$B$1-$A5)/7,1)*7+7*(COLUMN()-7),$F5="monthly",DATE(YEAR($A5),MONTH($A5)+CEILING(DATEDIF($A5,'13-week CF Forecast'!$B$1,"m")+1,1)+COLUMN()-7,DAY($A5)),$F5="quarterly",DATE(YEAR($A5),MONTH($A5)+3*CEILING((DATEDIF($A5,'13-week CF Forecast'!$B$1,"m")+1)/3,1)+(COLUMN()-7)*3,DAY($A5)),$F5="yearly",DATE(YEAR($A5)+CEILING((DATEDIF($A5,'13-week CF Forecast'!$B$1,"y")+1),1)+COLUMN()-7,MONTH($A5),DAY($A5)),TRUE,"") -> 46204 | T5: =IFERROR(ROWSDUMMYFUNCTION(UNNEST(PAIR2JSON('Recurring Transactions'!$A$1,'Recurring Transactions'!A5,'Recurring Transactions'!$B$1,'Recurring Transactions'!B5,'Recurring Transactions'!$C$1,'Recurring Transactions'!C5,'Recurring Transactions'!$D$1,'Recurring Transactions'!D5,'Recurring Transactions'!$E$1,'Recurring Transactions'!E5,'Recurring Transactions'!$F$1,'Recurring Transactions'!F5,"Payment schedule",VALUE(RANGE2JSON('Recurring Transactions'!F5,'Recurring Transactions'!G5:S5))))),"[{""First payment date"":""2025-01-01"",""Counterparty"":""Carrigan"",""Description"":""Carrigan"",""Amount"":""$3500"",""Category"":""Sales&Marketing Expenditures"",""Frequency"":""monthly"",""Payment schedule_0"":""2025-07-01""},{""First payment date"":""2025-01-01"",""Counterparty"":""C"&"arrigan"",""Description"":""Carrigan"",""Amount"":""$3500"",""Category"":""Sales&Marketing Expenditures"",""Frequency"":""monthly"",""Payment schedule_0"":""2025-08-01""},{""First payment date"":""2025-01-01"",""Counterparty"":""Carrigan"",""Description"":""Carrigan"",""Amount"":""$3500"",""C"&"ategory"":""Sales&Marketing Expenditures"",""Frequency"":""monthly"",""Payment schedule_0"":""2025-09-01""},{""First payment date"":""2025-01-01"",""Counterparty"":""Carrigan"",""Description"":""Carrigan"",""Amount"":""$3500"",""Category"":""Sales&Marketing Expenditures"",""Frequency"":"""&"monthly"",""Payment schedule_0"":""2025-10-01""},{""First payment date"":""2025-01-01"",""Counterparty"":""Carrigan"",""Description"":""Carrigan"",""Amount"":""$3500"",""Category"":""Sales&Marketing Expenditures"",""Frequency"":""monthly"",""Payment schedule_0"":""2025-11-01""},{""First p"&"ayment date"":""2025-01-01"",""Counterparty"":""Carrigan"",""Description"":""Carrigan"",""Amount"":""$3500"",""Category"":""Sales&Marketing Expenditures"",""Frequency"":""monthly"",""Payment schedule_0"":""2025-12-01""},{""First payment date"":""2025-01-01"",""Counterparty"":""Carrigan"","""&"Description"":""Carrigan"",""Amount"":""$3500"",""Category"":""Sales&Marketing Expenditures"",""Frequency"":""monthly"",""Payment schedule_0"":""2026-01-01""},{""First payment date"":""2025-01-01"",""Counterparty"":""Carrigan"",""Description"":""Carrigan"",""Amount"":""$3500"",""Category"":"""&"Sales&Marketing Expenditures"",""Frequency"":""monthly"",""Payment schedule_0"":""2026-02-01""},{""First payment date"":""2025-01-01"",""Counterparty"":""Carrigan"",""Description"":""Carrigan"",""Amount"":""$3500"",""Category"":""Sales&Marketing Expenditures"",""Frequency"":""monthly"","""&"Payment schedule_0"":""2026-03-01""},{""First payment date"":""2025-01-01"",""Counterparty"":""Carrigan"",""Description"":""Carrigan"",""Amount"":""$3500"",""Category"":""Sales&Marketing Expenditures"",""Frequency"":""monthly"",""Payment schedule_0"":""2026-04-01""},{""First payment dat"&"e"":""2025-01-01"",""Counterparty"":""Carrigan"",""Description"":""Carrigan"",""Amount"":""$3500"",""Category"":""Sales&Marketing Expenditures"",""Frequency"":""monthly"",""Payment schedule_0"":""2026-05-01""},{""First payment date"":""2025-01-01"",""Counterparty"":""Carrigan"",""Descriptio"&"n"":""Carrigan"",""Amount"":""$3500"",""Category"":""Sales&Marketing Expenditures"",""Frequency"":""monthly"",""Payment schedule_0"":""2026-06-01""},{""First payment date"":""2025-01-01"",""Counterparty"":""Carrigan"",""Description"":""Carrigan"",""Amount"":""$3500"",""Category"":""Sales&Mark"&"eting Expenditures"",""Frequency"":""monthly"",""Payment schedule_0"":""2026-07-01""}]") -> [{"First payment date":"2025-01-01","Counterparty":"Carrigan","Description":"Carrigan","Amount":"$3500","Category":"Sales&Marketing Expenditures","Frequency":"monthly","Payment schedule_0":"2025-07-01"},{"First payment date":"2025-01-01","Counterparty":"Carrigan","Description":"Carrigan","Amount":"$3500","Category":"Sales&Marketing Expenditures","Frequency":"monthly","Payment schedule_0":"2025-08-01"},{"First payment date":"2025-01-01","Counterparty":"Carrigan","Description":"Carrigan","Amount":"$3500","Category":"Sales&Marketing Expenditures","Frequency":"monthly","Payment schedule_0":"2025-09-01"},{"First payment date":"2025-01-01","Counterparty":"Carrigan","Description":"Carrigan","Amount":"$3500","Category":"Sales&Marketing Expenditures","Frequency":"monthly","Payment schedule_0":"2025-10-01"},{"First payment date":"2025-01-01","Counterparty":"Carrigan","Description":"Carrigan","Amount":"$3500","Category":"Sales&Marketing Expenditures","Frequency":"monthly","Payment schedule_0":"2025-11-01"},{"First payment date":"2025-01-01","Counterparty":"Carrigan","Description":"Carrigan","Amount":"$3500","Category":"Sales&Marketing Expenditures","Frequency":"monthly","Payment schedule_0":"2025-12-01"},{"First payment date":"2025-01-01","Counterparty":"Carrigan","Description":"Carrigan","Amount":"$3500","Category":"Sales&Marketing Expenditures","Frequency":"monthly","Payment schedule_0":"2026-01-01"},{"First payment date":"2025-01-01","Counterparty":"Carrigan","Description":"Carrigan","Amount":"$3500","Category":"Sales&Marketing Expenditures","Frequency":"monthly","Payment schedule_0":"2026-02-01"},{"First payment date":"2025-01-01","Counterparty":"Carrigan","Description":"Carrigan","Amount":"$3500","Category":"Sales&Marketing Expenditures","Frequency":"monthly","Payment schedule_0":"2026-03-01"},{"First payment date":"2025-01-01","Counterparty":"Carrigan","Description":"Carrigan","Amount":"$3500","Category":"Sales&Marketing Expenditures","Frequency":"monthly","Payment schedule_0":"2026-04-01"},{"First payment date":"2025-01-01","Counterparty":"Carrigan","Description":"Carrigan","Amount":"$3500","Category":"Sales&Marketing Expenditures","Frequency":"monthly","Payment schedule_0":"2026-05-01"},{"First payment date":"2025-01-01","Counterparty":"Carrigan","Description":"Carrigan","Amount":"$3500","Category":"Sales&Marketing Expenditures","Frequency":"monthly","Payment schedule_0":"2026-06-01"},{"First payment date":"2025-01-01","Counterparty":"Carrigan","Description":"Carrigan","Amount":"$3500","Category":"Sales&Marketing Expenditures","Frequency":"monthly","Payment schedule_0":"2026-07-01"}] | U5: Chase Inc
